
<wandb.sdk.wandb_run.Run object at 0x28cad4890>
Traceback (most recent call last):
  File "<stdin>", line 1, in <module>
  File "/Users/brianliu03/miniconda3/envs/mlenv/lib/python3.11/site-packages/datasets/load.py", line 2129, in load_dataset
    builder_instance = load_dataset_builder(
                       ^^^^^^^^^^^^^^^^^^^^^
  File "/Users/brianliu03/miniconda3/envs/mlenv/lib/python3.11/site-packages/datasets/load.py", line 1815, in load_dataset_builder
    dataset_module = dataset_module_factory(
                     ^^^^^^^^^^^^^^^^^^^^^^^
  File "/Users/brianliu03/miniconda3/envs/mlenv/lib/python3.11/site-packages/datasets/load.py", line 1446, in dataset_module_factory
    ).get_module()
      ^^^^^^^^^^^^
  File "/Users/brianliu03/miniconda3/envs/mlenv/lib/python3.11/site-packages/datasets/load.py", line 859, in get_module
    patterns = get_data_patterns(base_path)
               ^^^^^^^^^^^^^^^^^^^^^^^^^^^^
  File "/Users/brianliu03/miniconda3/envs/mlenv/lib/python3.11/site-packages/datasets/data_files.py", line 460, in get_data_patterns
    raise EmptyDatasetError(f"The directory at {base_path} doesn't contain any data files") from None
datasets.data_files.EmptyDatasetError: The directory at /Users/brianliu03/Documents/Projects/sentiment-analysis/sst2 doesn't contain any data files
Traceback (most recent call last):
  File "<stdin>", line 1, in <module>
NameError: name 'dataset' is not defined
Traceback (most recent call last):
  File "<stdin>", line 1, in <module>
NameError: name 'dataset' is not defined
Error in sys.excepthook:
Traceback (most recent call last):
  File "/Users/brianliu03/miniconda3/envs/mlenv/lib/python3.11/site-packages/wandb/sdk/lib/exit_hooks.py", line 41, in exc_handler
    def exc_handler(
KeyboardInterrupt
Original exception was:
KeyboardInterrupt
KeyboardInterrupt
KeyboardInterrupt
KeyboardInterrupt